Workbook

Sheet Presupuesto
A1: Categoría | B1: Fecha | C1: Día | D1: Horario | E1: Concepto o Actividad | F1: Notas | G1: Coste total | H1: Coste al dia | I1: Coste Raul | J1: Coste Guillermo | K1: Coste Silvia | L1: Precio por persona (NOK) | M1: Estado | N1: Plan | O1: Enlace | P1: Fuente del precio (consultado 13/10/2026)
A2: Seguro | B2: 16/10 al 20 o 24/10 | C2: Varios | E2: Seguro Viaje | G2: 131.4 | I2: 46.85 | J2: 46.85 | K2: 37.7 | M2: Reservado
A3: Vuelo Ida | B3: 46311 | C3: Viernes | D3: 06:05 - 12:20 | E3: Vuelo Ida (VLC-FRA-OSL) | F3: Estar en el aeropuerto de Valencia a las 04:30–05:00 para facturar las maletas de 23 kg. | I3: 399.76 | J3: 403.76 | K3: 434.76 | M3: Reservado
A4: Tren | B4: 46311 | C4: Viernes | D4: 13:15 - 14:00 | E4: Tren Gardermoen a OSLO S (Vy) | F4: Descargar la app de Vy. 124 NOK en la app (99 NOK comprando antes; 124–190 NOK en máquina); 25–30 min. HUELGA de maquinistas activa: el 16/10 Vy prevé cancelar el 51 % de los RE10 y el 6 % de los RE11. Mirar la app al aterrizar, antes de comprar. | G4: =IF($L4="","",SUM(I4:K4)) | I4: =IF($L4="","",ROUND($L4/'Parámetros'!$B$3,2)) | J4: =IF($L4="","",ROUND($L4/'Parámetros'!$B$3,2)) | K4: =IF($L4="","",ROUND($L4/'Parámetros'!$B$3,2)) | L4: 124 | M4: Pendiente | N4: A | O4: https://www.vy.no/en | P4: https://www.oslo-spirit.com/de/reisefuehrer/flytoget-vs-zug/ · https://www.vy.no/togstreik
A5: Tren | B5: 46311 | C5: Viernes | D5: 13:15 - 13:35 | E5: Alternativa: Flytoget aeropuerto → Oslo S | F5: Si no salen trenes de Vy. 19 min, cada 10 min. 243 NOK (a veces ofertas desde 199). Flytoget también tiene algunos maquinistas en huelga. | G5: =IF($L5="","",SUM(I5:K5)) | I5: =IF($L5="","",ROUND($L5/'Parámetros'!$B$3,2)) | J5: =IF($L5="","",ROUND($L5/'Parámetros'!$B$3,2)) | K5: =IF($L5="","",ROUND($L5/'Parámetros'!$B$3,2)) | L5: 243 | M5: Alternativa | N5: A | O5: https://flytoget.no/en/ | P5: https://www.oslo-spirit.com/de/reisefuehrer/flytoget-vs-zug/
A6: Autobús | B6: 46311 | C6: Viernes | D6: 13:30 - 14:30 | E6: Alternativa: Flybussen aeropuerto → Oslo bussterminal | F6: No depende de la huelga de trenes. 40–50 min. Unos 220–260 NOK; más barato comprando antes en la web. | G6: =IF($L6="","",SUM(I6:K6)) | I6: =IF($L6="","",ROUND($L6/'Parámetros'!$B$3,2)) | J6: =IF($L6="","",ROUND($L6/'Parámetros'!$B$3,2)) | K6: =IF($L6="","",ROUND($L6/'Parámetros'!$B$3,2)) | L6: 240 | M6: Alternativa | N6: A | O6: https://www.flybussen.no/en | P6: https://www.oslo-spirit.com/de/reisefuehrer/flytoget-vs-zug/
A7: Consigna | B7: 46311 | C7: Viernes | D7: 14:00 - 16:00 | E7: Consigna viernes hasta el check-in (1 maleta por persona) | F7: La casa abre a las 16:00. Primero preguntar al anfitrión si guarda las maletas antes. Si no: LuggageHero junto a Oslo S (~15 NOK/h por maleta + 24 NOK de servicio) o taquillas de Oslo S (~129–299 NOK por taquilla y 24 h). | G7: =IF($L7="","",SUM(I7:K7)) | I7: =IF($L7="","",ROUND($L7/'Parámetros'!$B$3,2)) | J7: =IF($L7="","",ROUND($L7/'Parámetros'!$B$3,2)) | K7: =IF($L7="","",ROUND($L7/'Parámetros'!$B$3,2)) | L7: 54 | M7: Opcional | O7: https://luggagehero.com/oslo/oslo-central-station/ | P7: https://luggagehero.com/oslo/oslo-central-station/ · https://thehiddennorth.com/where-to-store-luggage-in-norway/
A8: Comida | B8: 46311 | C8: Viernes | D8: 14:15 - 15:00 | E8: Comida rápida en Oslo S / Bjørvika | F8: Estimación: almuerzo informal 120–220 NOK por persona. | G8: =IF($L8="","",SUM(I8:K8)) | I8: =IF($L8="","",ROUND($L8/'Parámetros'!$B$3,2)) | J8: =IF($L8="","",ROUND($L8/'Parámetros'!$B$3,2)) | K8: =IF($L8="","",ROUND($L8/'Parámetros'!$B$3,2)) | L8: 150 | M8: Estimación | P8: https://www.oslo-spirit.com/guides/oslo-daily-costs/
A9: Visita | B9: 46311 | C9: Viernes | D9: 15:00 - 16:00 | E9: Ópera de Oslo (tejado) + exterior del MUNCH + Bjørvika | F9: Gratis. A 5–10 min a pie de Oslo S. Subir al tejado de la Ópera solo si está seco y sin hielo. | G9: =IF($L9="","",SUM(I9:K9)) | I9: =IF($L9="","",ROUND($L9/'Parámetros'!$B$3,2)) | J9: =IF($L9="","",ROUND($L9/'Parámetros'!$B$3,2)) | K9: =IF($L9="","",ROUND($L9/'Parámetros'!$B$3,2)) | L9: 0 | M9: Previsto | N9: A | O9: https://operaen.no/en/
A10: Alojamiento | B10: 46311 | C10: Viernes | D10: 16:00 - 17:00 | E10: Recoger maletas y check-in en la casa de Oslo | F10: Check-in desde las 16:00. Si la casa no está cerca de Oslo S: 1 billete sencillo de Ruter (46 NOK). | M10: Previsto
A11: Alojamiento | B11: 16/10 al 18/10 | C11: Varios | D11: 16:00 - 10:00 | E11: Casa en OSLO (2 Noches) | F11: Check-in 16:00 del viernes; check-out 10:00 del domingo. | G11: 532.88 | I11: 177.63 | J11: 177.63 | K11: 177.63 | M11: Reservado
A12: Compra | B12: 46311 | C12: Viernes | D12: 17:15 - 18:00 | E12: Supermercado: desayunos de sábado y domingo, agua y snacks | F12: Estimación. Cocinar con productos del súper sale a 150–200 NOK por persona y día. | G12: =IF($L12="","",SUM(I12:K12)) | I12: =IF($L12="","",ROUND($L12/'Parámetros'!$B$3,2)) | J12: =IF($L12="","",ROUND($L12/'Parámetros'!$B$3,2)) | K12: =IF($L12="","",ROUND($L12/'Parámetros'!$B$3,2)) | L12: 100 | M12: Estimación | P12: https://www.oslo-spirit.com/guides/oslo-daily-costs/
A13: Museo | B13: 46311 | C13: Viernes | D13: 18:00 - 19:30 | E13: Opcional: MUNCH con tarifa de tarde | F13: Si llueve o queda energía. Viernes abre hasta las 21:00. Franja 18:00–21:00: 200 NOK (de día 280 NOK; menores de 25: 100 NOK). Reservar la franja online. | G13: =IF($L13="","",SUM(I13:K13)) | I13: =IF($L13="","",ROUND($L13/'Parámetros'!$B$3,2)) | J13: =IF($L13="","",ROUND($L13/'Parámetros'!$B$3,2)) | K13: =IF($L13="","",ROUND($L13/'Parámetros'!$B$3,2)) | L13: 200 | M13: Opcional | O13: https://munch.no/en/buy-tickets/ | P13: https://www.munch.no/en/visit-us/opening-hours/
A14: Comida | B14: 46311 | C14: Viernes | D14: 19:30 - 21:00 | E14: Cena en Oslo | F14: Estimación: restaurante medio 280–420 NOK por persona con una bebida; food hall 200–280 NOK. | G14: =IF($L14="","",SUM(I14:K14)) | I14: =IF($L14="","",ROUND($L14/'Parámetros'!$B$3,2)) | J14: =IF($L14="","",ROUND($L14/'Parámetros'!$B$3,2)) | K14: =IF($L14="","",ROUND($L14/'Parámetros'!$B$3,2)) | L14: 300 | M14: Estimación | P14: https://www.oslo-spirit.com/guides/oslo-daily-costs/
A15: Auroras | B15: 46311 | C15: Viernes | D15: 21:00 | E15: Mirar la previsión de auroras (NOAA + Yr) | F15: Salir solo si Kp ≥ 5, el cielo está despejado y la vuelta está asegurada. | M15: Previsto | O15: https://www.swpc.noaa.gov/products/aurora-30-minute-forecast
A16: Barco | B16: 46312 | C16: Sábado | D16: 09:45 - 12:30 | E16: Crucero Brim Explorer — Silent Oslo Fjord Cruise | F16: Sale a las 10:00 de Rådhusbrygge 2 (estar 15 min antes); 2,5 h. Salidas diarias a las 10:00 y 13:30 todo el año. Desde el 1/10: 15 % de descuento + bebida caliente gratis (690 → 586,50 NOK). Salones interiores calefactados y cafetería. | G16: =IF($L16="","",SUM(I16:K16)) | I16: =IF($L16="","",ROUND($L16/'Parámetros'!$B$3,2)) | J16: =IF($L16="","",ROUND($L16/'Parámetros'!$B$3,2)) | K16: =IF($L16="","",ROUND($L16/'Parámetros'!$B$3,2)) | L16: 586.5 | M16: Pendiente | N16: A | O16: https://brimexplorer.com/tours/silent-oslo-fjord-cruise | P16: https://brimexplorer.com/tours/silent-oslo-fjord-cruise
A17: Barco | B17: 46312 | C17: Sábado | D17: 10:00 - 12:30 | E17: Alternativa: ferry B1 a Hovedøya (ida y vuelta) | F17: Solo si el día es seco y los caminos no tienen hielo. 2 billetes sencillos de Ruter zona 1 (46 NOK cada uno). Mirar la hora del ferry de vuelta antes de desembarcar. | G17: =IF($L17="","",SUM(I17:K17)) | I17: =IF($L17="","",ROUND($L17/'Parámetros'!$B$3,2)) | J17: =IF($L17="","",ROUND($L17/'Parámetros'!$B$3,2)) | K17: =IF($L17="","",ROUND($L17/'Parámetros'!$B$3,2)) | L17: 92 | M17: Alternativa | N17: A2 | O17: https://ruter.no/en | P17: https://ruter.no/nyheter/alt-om-billettpriser
A18: Museo | B18: 46312 | C18: Sábado | D18: 10:00 - 12:30 | E18: Alternativa (lluvia fuerte): MUNCH | F18: Plan C. 280 NOK (10:00–18:00). El sábado abre hasta las 21:00. | G18: =IF($L18="","",SUM(I18:K18)) | I18: =IF($L18="","",ROUND($L18/'Parámetros'!$B$3,2)) | J18: =IF($L18="","",ROUND($L18/'Parámetros'!$B$3,2)) | K18: =IF($L18="","",ROUND($L18/'Parámetros'!$B$3,2)) | L18: 280 | M18: Alternativa | N18: C | O18: https://munch.no/en/buy-tickets/ | P18: https://www.munch.no/en/visit-us/opening-hours/
A19: Comida | B19: 46312 | C19: Sábado | D19: 12:30 - 13:30 | E19: Comida en Aker Brygge | F19: Estimación. Aker Brygge es un 30–50 % más caro que otras zonas; buscar un 'dagsmeny' (menú del día). | G19: =IF($L19="","",SUM(I19:K19)) | I19: =IF($L19="","",ROUND($L19/'Parámetros'!$B$3,2)) | J19: =IF($L19="","",ROUND($L19/'Parámetros'!$B$3,2)) | K19: =IF($L19="","",ROUND($L19/'Parámetros'!$B$3,2)) | L19: 220 | M19: Estimación | P19: https://www.oslo-spirit.com/guides/oslo-daily-costs/
A20: Visita | B20: 46312 | C20: Sábado | D20: 13:30 - 14:15 | E20: Ayuntamiento de Oslo (Rådhuset) | F20: Gratis. Lunes a sábado 09:00–16:00; domingos cerrado. El 17/10 no figura entre los cierres especiales (consultado el 13/10). Control de seguridad: puede haber cola. | G20: =IF($L20="","",SUM(I20:K20)) | I20: =IF($L20="","",ROUND($L20/'Parámetros'!$B$3,2)) | J20: =IF($L20="","",ROUND($L20/'Parámetros'!$B$3,2)) | K20: =IF($L20="","",ROUND($L20/'Parámetros'!$B$3,2)) | L20: 0 | M20: Previsto | N20: A | O20: https://www.oslo.kommune.no/english/oslo-city-hall/opening-hours/ | P20: https://www.oslo.kommune.no/radhuset/radhusets-apningstider/
A21: Visita | B21: 46312 | C21: Sábado | D21: 14:30 - 15:45 | E21: Fortaleza de Akershus (exterior) | F21: Recinto gratis, abierto todos los días de 06:00 a 21:00. El castillo por dentro solo abre del 2/7 al 31/8. | G21: =IF($L21="","",SUM(I21:K21)) | I21: =IF($L21="","",ROUND($L21/'Parámetros'!$B$3,2)) | J21: =IF($L21="","",ROUND($L21/'Parámetros'!$B$3,2)) | K21: =IF($L21="","",ROUND($L21/'Parámetros'!$B$3,2)) | L21: 0 | M21: Previsto | N21: A | O21: https://forsvarsbygg.no/no/festningene/akershus-festning/akershus-fortress/practical-information | P21: https://forsvarsbygg.no/no/festningene/akershus-festning/akershus-fortress/practical-information
A22: Paseo | B22: 46312 | C22: Sábado | D22: 16:00 - 18:15 | E22: Karl Johans gate → Catedral → Parlamento → Palacio Real (exterior) | F22: Gratis. Puesta de sol hacia las 18:15. Refugio si hace frío: MUNCH (sábado hasta las 21:00). | G22: =IF($L22="","",SUM(I22:K22)) | I22: =IF($L22="","",ROUND($L22/'Parámetros'!$B$3,2)) | J22: =IF($L22="","",ROUND($L22/'Parámetros'!$B$3,2)) | K22: =IF($L22="","",ROUND($L22/'Parámetros'!$B$3,2)) | L22: 0 | M22: Previsto | N22: A
A23: Compra | B23: 46312 | C23: Sábado | D23: 18:15 - 19:00 | E23: Supermercado: cena del domingo y desayuno del lunes | F23: En Noruega casi todos los supermercados cierran en domingo: hay que comprarlo hoy. | G23: =IF($L23="","",SUM(I23:K23)) | I23: =IF($L23="","",ROUND($L23/'Parámetros'!$B$3,2)) | J23: =IF($L23="","",ROUND($L23/'Parámetros'!$B$3,2)) | K23: =IF($L23="","",ROUND($L23/'Parámetros'!$B$3,2)) | L23: 200 | M23: Estimación | P23: https://www.oslo-spirit.com/guides/oslo-daily-costs/
A24: Comida | B24: 46312 | C24: Sábado | D24: 19:30 - 21:00 | E24: Cena en Oslo | F24: Estimación: restaurante medio 280–420 NOK por persona con una bebida. | G24: =IF($L24="","",SUM(I24:K24)) | I24: =IF($L24="","",ROUND($L24/'Parámetros'!$B$3,2)) | J24: =IF($L24="","",ROUND($L24/'Parámetros'!$B$3,2)) | K24: =IF($L24="","",ROUND($L24/'Parámetros'!$B$3,2)) | L24: 300 | M24: Estimación | P24: https://www.oslo-spirit.com/guides/oslo-daily-costs/
A25: Auroras | B25: 46312 | C25: Sábado | D25: 21:30 - 00:30 | E25: Opcional: salida a ver auroras (Ekebergparken) | F25: Solo si Kp ≥ 5, cielo despejado y vuelta asegurada. Tranvía de ida y vuelta: 2 × 46 NOK. Alternativa más oscura: Sognsvann (final del metro), si hay metro de vuelta. | G25: =IF($L25="","",SUM(I25:K25)) | I25: =IF($L25="","",ROUND($L25/'Parámetros'!$B$3,2)) | J25: =IF($L25="","",ROUND($L25/'Parámetros'!$B$3,2)) | K25: =IF($L25="","",ROUND($L25/'Parámetros'!$B$3,2)) | L25: 92 | M25: Opcional | O25: https://www.swpc.noaa.gov/products/aurora-30-minute-forecast | P25: https://ruter.no/nyheter/alt-om-billettpriser
A26: Alojamiento | B26: 46313 | C26: Domingo | D26: 08:30 - 10:00 | E26: Desayuno, maletas y check-out de la casa de Oslo | F26: Check-out a las 10:00. | M26: Previsto
A27: Consigna | B27: 46313 | C27: Domingo | D27: 10:00 - 17:00 | E27: Consigna para guardar maletas Domingo | F27: Taquillas de Oslo S (planta inferior del vestíbulo Hovedhallen): ~129 NOK pequeña – ~299 NOK grande por 24 h; sin confirmar que quepa una maleta de 23 kg. Alternativa: LuggageHero junto a Oslo S, sin límite de tamaño (~15 NOK/h por maleta + 24 NOK de servicio). Estimación por persona. | G27: =IF($L27="","",SUM(I27:K27)) | I27: =IF($L27="","",ROUND($L27/'Parámetros'!$B$3,2)) | J27: =IF($L27="","",ROUND($L27/'Parámetros'!$B$3,2)) | K27: =IF($L27="","",ROUND($L27/'Parámetros'!$B$3,2)) | L27: 130 | M27: Pendiente | O27: https://luggagehero.com/oslo/oslo-central-station/ | P27: https://thehiddennorth.com/where-to-store-luggage-in-norway/ · https://luggagehero.com/oslo/oslo-central-station/
A28: Transporte | B28: 46313 | C28: Domingo | D28: 10:15 | E28: Billete Ruter de 24 h, zona 1 (app Ruter) | F28: 137 NOK. Cubre el metro a Majorstuen, a Holmenkollen y la vuelta (≈ 3 billetes sencillos de 46 NOK), y el bus 30 a Bygdøy si hay plan B. | G28: =IF($L28="","",SUM(I28:K28)) | I28: =IF($L28="","",ROUND($L28/'Parámetros'!$B$3,2)) | J28: =IF($L28="","",ROUND($L28/'Parámetros'!$B$3,2)) | K28: =IF($L28="","",ROUND($L28/'Parámetros'!$B$3,2)) | L28: 137 | M28: Pendiente | O28: https://ruter.no/en | P28: https://www.thelocal.no/20260316/is-the-oslo-pass-worth-getting-when-visiting-the-norwegian-capital · https://ruter.no/nyheter/alt-om-billettpriser
A29: Visita | B29: 46313 | C29: Domingo | D29: 10:45 - 12:00 | E29: Parque Vigeland | F29: Gratis, abierto siempre. Metro hasta Majorstuen + 10 min a pie. Solo si los caminos no tienen hielo. | G29: =IF($L29="","",SUM(I29:K29)) | I29: =IF($L29="","",ROUND($L29/'Parámetros'!$B$3,2)) | J29: =IF($L29="","",ROUND($L29/'Parámetros'!$B$3,2)) | K29: =IF($L29="","",ROUND($L29/'Parámetros'!$B$3,2)) | L29: 0 | M29: Previsto | N29: A | O29: https://www.visitoslo.com/en/product/?tlp=1818293&name=Vigeland-Sculpture-Park
A30: Visita | B30: 46313 | C30: Domingo | D30: 12:30 - 14:15 | E30: Holmenkollen: museo del esquí + torre de salto | F30: Metro línea 1 desde Majorstuen (~20 min) + 10–15 min de subida a pie. Octubre: 10:00–16:00. 200 NOK (menores de 30: 150 NOK). La torre cierra del 13 al 16/10 por mantenimiento. Simulador de salto: 130 NOK aparte. Si hay niebla, no compensa: plan B. | G30: =IF($L30="","",SUM(I30:K30)) | I30: =IF($L30="","",ROUND($L30/'Parámetros'!$B$3,2)) | J30: =IF($L30="","",ROUND($L30/'Parámetros'!$B$3,2)) | K30: =IF($L30="","",ROUND($L30/'Parámetros'!$B$3,2)) | L30: 200 | M30: Pendiente | N30: A | O30: https://holmenkollen.com/en/ | P30: https://holmenkollen.com/en/apningstider/
A31: Comida | B31: 46313 | C31: Domingo | D31: 14:15 - 15:00 | E31: Comida (Holmenkollen o centro) | F31: Estimación: almuerzo informal 120–220 NOK. | G31: =IF($L31="","",SUM(I31:K31)) | I31: =IF($L31="","",ROUND($L31/'Parámetros'!$B$3,2)) | J31: =IF($L31="","",ROUND($L31/'Parámetros'!$B$3,2)) | K31: =IF($L31="","",ROUND($L31/'Parámetros'!$B$3,2)) | L31: 180 | M31: Estimación | P31: https://www.oslo-spirit.com/guides/oslo-daily-costs/
A32: Café | B32: 46313 | C32: Domingo | D32: 15:45 - 16:30 | E32: Opcional: café en Aker Brygge / Tjuvholmen | F32: Café 50–65 NOK. | G32: =IF($L32="","",SUM(I32:K32)) | I32: =IF($L32="","",ROUND($L32/'Parámetros'!$B$3,2)) | J32: =IF($L32="","",ROUND($L32/'Parámetros'!$B$3,2)) | K32: =IF($L32="","",ROUND($L32/'Parámetros'!$B$3,2)) | L32: 60 | M32: Opcional | P32: https://www.oslo-spirit.com/guides/oslo-daily-costs/
A33: Visita | B33: 46313 | C33: Domingo | D33: 11:00 - 14:45 | E33: Alternativa (hielo, lluvia o niebla): Bygdøy — FRAM + Kon-Tiki | F33: Sustituye a Vigeland + Holmenkollen. Bus 30 (incluido en el billete de 24 h). Entrada combinada FRAM + Kon-Tiki: 325 NOK (sueltas: 180 NOK cada una). FRAM en octubre: 10:00–17:00. | G33: =IF($L33="","",SUM(I33:K33)) | I33: =IF($L33="","",ROUND($L33/'Parámetros'!$B$3,2)) | J33: =IF($L33="","",ROUND($L33/'Parámetros'!$B$3,2)) | K33: =IF($L33="","",ROUND($L33/'Parámetros'!$B$3,2)) | L33: 325 | M33: Alternativa | N33: B | O33: https://frammuseum.no/en/plan-your-visit/ | P33: https://frammuseum.no/en/plan-your-visit/ · https://www.kon-tiki.no/en/
A34: Museo | B34: 46313 | C34: Domingo | D34: 15:30 - 16:45 | E34: Alternativa: MUNCH (si no se ha visitado) | F34: Plan B. El domingo cierra a las 18:00. 280 NOK. | G34: =IF($L34="","",SUM(I34:K34)) | I34: =IF($L34="","",ROUND($L34/'Parámetros'!$B$3,2)) | J34: =IF($L34="","",ROUND($L34/'Parámetros'!$B$3,2)) | K34: =IF($L34="","",ROUND($L34/'Parámetros'!$B$3,2)) | L34: 280 | M34: Alternativa | N34: B | O34: https://munch.no/en/buy-tickets/ | P34: https://www.munch.no/en/visit-us/opening-hours/
A35: Consigna | B35: 46313 | C35: Domingo | D35: 16:45 - 17:15 | E35: Recoger las maletas en Oslo S | M35: Previsto
A36: Tren | B36: 46313 | C36: Domingo | D36: 17:30 - 18:10 | E36: Tren OSLO a Drammen | F36: Vy, ~36 min, salidas cada 15 min aprox. 110–160 NOK (Minipris, más barato comprando antes). Antes figuraba 07:00–13:00: con check-out a las 10:00 y la consigna hasta las 17:00, el tren va por la tarde. Huelga: mirar la app por la mañana y, si hay cancelaciones, adelantar la salida. | G36: =IF($L36="","",SUM(I36:K36)) | I36: =IF($L36="","",ROUND($L36/'Parámetros'!$B$3,2)) | J36: =IF($L36="","",ROUND($L36/'Parámetros'!$B$3,2)) | K36: =IF($L36="","",ROUND($L36/'Parámetros'!$B$3,2)) | L36: 135 | M36: Pendiente | O36: https://www.vy.no/en | P36: https://www.rome2rio.com/s/Oslo/Drammen · https://www.vy.no/togstreik
A37: Alojamiento | B37: 46313 | C37: Domingo | D37: 18:15 | E37: Check-in en Forenom Serviced Apartments Drammen | F37: Tollbugata 10–12, a 2–5 min a pie de Drammen stasjon. Check-in desde las 16:00. Cena con la compra del sábado. | M37: Previsto | O37: https://www.visitnorway.com/listings/forenom-serviced-appartments-drammen/269387/
A38: Alojamiento | B38: 18/10 al 20/10 | C38: Varios | D38: 16:00 - 11:00 | E38: Forenom Serviced Apartments Drammen | G38: 220.93 | I38: 73.64 | J38: 73.64 | K38: 73.64 | M38: Reservado
A39: Alojamiento | B39: 18/10 al 24/10 | C39: Varios | D39: 16:00 - 11:00 | E39: Forenom Serviced Apartments Drammen | G39: 531.56 | H39: 88.59 | I39: 236.25 | J39: 236.25 | K39: 59.06 | M39: Reservado
A41: PRESUPUESTO TOTAL | F41: Reservado + pendiente + estimaciones del plan A (sin opcionales ni alternativas) | G41: =SUM(I41:K41) | I41: =SUM(I2:I39)-SUMIF($M$2:$M$39,"Opcional",I2:I39)-SUMIF($M$2:$M$39,"Alternativa",I2:I39) | J41: =SUM(J2:J39)-SUMIF($M$2:$M$39,"Opcional",J2:J39)-SUMIF($M$2:$M$39,"Alternativa",J2:J39) | K41: =SUM(K2:K39)-SUMIF($M$2:$M$39,"Opcional",K2:K39)-SUMIF($M$2:$M$39,"Alternativa",K2:K39)
...

Sheet Parámetros
A1: Parámetros y leyenda
A3: Tipo de cambio (NOK por 1 €) | B3: 10.6955 | C3: Referencia del BCE del 12/10/2026. Si lo cambias, todos los costes en € se recalculan.
A4: Fuente | B4: https://www.ecb.europa.eu/stats/policy_and_exchange_rates/euro_reference_exchange_rates/html/eurofxref-graph-nok.en.html
A6: Estado | B6: Significado | C6: ¿Suma en el total?
A7: Reservado | B7: Ya pagado o reservado | C7: Sí
A8: Pendiente | B8: Hay que comprarlo o reservarlo | C8: Sí
A9: Estimación | B9: Gasto aproximado (comidas, supermercado) | C9: Sí
A10: Previsto | B10: Actividad gratuita o sin nada que comprar | C10: Sí (0 €)
A11: Opcional | B11: Solo si se hace | C11: No (aparece aparte)
A12: Alternativa | B12: Sustituye a otra actividad si cambia el tiempo o hay huelga | C12: No
A14: Cómo se usa
A15: · La columna L (Precio por persona, NOK) está en azul: es el dato que se edita. Las columnas de coste por persona en € se calculan solas.
A16: · Las filas de Seguro, Vuelo y Alojamiento son los datos originales de la hoja (en €), sin cambios.
A17: · Precios consultados el 13/10/2026 en las fuentes de la columna P. Pueden cambiar: comprobar antes de comprar.
A18: · Las filas en gris y cursiva son alternativas: aparecen con su precio para comparar, pero no suman.
A19: · Colores de fondo: azul = viernes 16, verde = sábado 17, naranja = domingo 18.

Sheet Resumen
A1: Gasto por persona en Oslo (16–18 oct), plan A
A3: Día | B3: Fecha | C3: Plan A (NOK) | D3: Plan A (€) | E3: Opcionales (NOK) | F3: Opcionales (€)
A4: Viernes | B4: 46311 | C4: =SUMIFS(Presupuesto!$L$2:$L$39,Presupuesto!$B$2:$B$39,$B4,Presupuesto!$M$2:$M$39,"<>Opcional",Presupuesto!$M$2:$M$39,"<>Alternativa") | D4: =C4/'Parámetros'!$B$3 | E4: =SUMIFS(Presupuesto!$L$2:$L$39,Presupuesto!$B$2:$B$39,$B4,Presupuesto!$M$2:$M$39,"Opcional") | F4: =E4/'Parámetros'!$B$3
A5: Sábado | B5: 46312 | C5: =SUMIFS(Presupuesto!$L$2:$L$39,Presupuesto!$B$2:$B$39,$B5,Presupuesto!$M$2:$M$39,"<>Opcional",Presupuesto!$M$2:$M$39,"<>Alternativa") | D5: =C5/'Parámetros'!$B$3 | E5: =SUMIFS(Presupuesto!$L$2:$L$39,Presupuesto!$B$2:$B$39,$B5,Presupuesto!$M$2:$M$39,"Opcional") | F5: =E5/'Parámetros'!$B$3
A6: Domingo | B6: 46313 | C6: =SUMIFS(Presupuesto!$L$2:$L$39,Presupuesto!$B$2:$B$39,$B6,Presupuesto!$M$2:$M$39,"<>Opcional",Presupuesto!$M$2:$M$39,"<>Alternativa") | D6: =C6/'Parámetros'!$B$3 | E6: =SUMIFS(Presupuesto!$L$2:$L$39,Presupuesto!$B$2:$B$39,$B6,Presupuesto!$M$2:$M$39,"Opcional") | F6: =E6/'Parámetros'!$B$3
A7: Total por persona | C7: =SUM(C4:C6) | D7: =SUM(D4:D6) | E7: =SUM(E4:E6) | F7: =SUM(F4:F6)
A8: Total para los tres | C8: =C7*3 | D8: =D7*3 | E8: =E7*3 | F8: =F7*3
A10: Si cambiamos de plan (diferencia por persona)
A11: Cambio | C11: NOK | D11: €
A12: Flytoget en lugar del tren de Vy | C12: =Presupuesto!L5-Presupuesto!L4 | D12: =C12/'Parámetros'!$B$3
A13: Flybussen en lugar del tren de Vy | C13: =Presupuesto!L6-Presupuesto!L4 | D13: =C13/'Parámetros'!$B$3
A14: Hovedøya en lugar del crucero | C14: =Presupuesto!L17-Presupuesto!L16 | D14: =C14/'Parámetros'!$B$3
A15: MUNCH en lugar del crucero (lluvia fuerte) | C15: =Presupuesto!L18-Presupuesto!L16 | D15: =C15/'Parámetros'!$B$3
A16: FRAM + Kon-Tiki en lugar de Holmenkollen | C16: =Presupuesto!L33-Presupuesto!L30 | D16: =C16/'Parámetros'!$B$3
A17: FRAM + Kon-Tiki + MUNCH en lugar de Holmenkollen | C17: =Presupuesto!L33+Presupuesto!L34-Presupuesto!L30 | D17: =C17/'Parámetros'!$B$3
A19: Las cifras salen de la hoja Presupuesto (texto verde = enlace a otra hoja).
